Workbook

Sheet LOG
F1: PO Box 663
F2: 1721 HCR 3106
F3: Hillsboro, Texas 76645
F4: Office: 254-582-0205
F5: BobcatContracting.com
A6: Hydrotest Log
A7: Asset Owner: | C7: Atmos Energy | F7: PO/AFE: | G7: 180.64635
A8: Contractor: | C8: Bobcat Contracting | F8: Location: | G8: Henrietta, Tx
A9: Job Number: | C9: ATM-4422 | F9: Date: | G9: 46263
A11: Deadweights: | C11: S/N: | D11: 5496 | E11: Mfg: | F11: Refinery | G11: Calibration Date: | I11: 46150
A12: Pressure Recorder: | C12: S/N: | D12: 13045 | E12: Mfg: | F12: Tech-Cal | G12: Calibration Date: | I12: 46150
A13: Ambient Temp: | C13: S/N: | D13: 10908 | E13: (L) Mfg: | F13: Tech-Cal | G13: Calibration Date: | I13: 46150
A14: Pipe Temp: | C14: S/N: | D14: 10910 | E14: (H) Mfg: | F14: Tech-Cal | G14: Calibration Date: | I14: 46150
A15: Ground Temp: | C15: S/N: | D15: 10912 | E15: (M) Mfg: | F15: Tech-Cal | G15: Calibration Date: | I15: 46150
A16: Digital Gauge: | C16: S/N: | D16: 021863 | E16: Mfg: | F16: AMETEK | G16: Calibration Date: | I16: 46150
A17: Facility Data
A18: Minimum Test Pressure: | D18: 4120 | E18: Maximum Test Pressure: | H18: 4170
A19: Begin GPS: | B19: 33.7132610, -98.1230730 | E19: Total Footage: | G19: 2046
A20: End GPS: | B20: 33.7180270, -98.1248640 | E20: Test Pump Used/Gallons per stroke | H20: PDQ - 0.0043
A21: Hydrostatic Test Field Data
A22: Time: | B22: Pressure | C22: Ambient | D22: Pipe | E22: Ground | F22: Comments / Remarks
A23: 0.21111111 | B23: 0 | C23: 68 | D23: 72 | E23: 84 | F23: Pressure is at 0 psi
A24: 0.25069444 | B24: 3119 | C24: 68 | D24: 72 | E24: 84 | F24: Reached 75% begin 30 minute hold
A25: 0.31458333 | B25: 3100 | C25: 64 | D25: 72 | E25: 84 | F25: End 30 minute hold / Begin pressuring up
A26: 0.37777778 | B26: 4158 | C26: 72 | D26: 72 | E26: 84 | F26: Reached test pressure / Begin 15 minute hold
A27: 0.39583333 | B27: 4160 | C27: 76 | D27: 72 | E27: 83 | F27: Begin 8 hour test
A28: 0.40625 | B28: 4167 | C28: 77 | D28: 72 | E28: 82 | F28: Bled down 10 oz 4167-4159
A29: 0.41666667 | B29: 4162 | C29: 78 | D29: 72 | E29: 82 | F29: Bled down 17 oz 4167-4148
A30: 0.42708333 | B30: 4148 | C30: 80 | D30: 72 | E30: 82 | F30: Sunny
A31: 0.4375 | B31: 4153 | C31: 81 | D31: 72 | E31: 82 | F31: Sunny
A32: 0.44791667 | B32: 4157 | C32: 82 | D32: 72 | E32: 81 | F32: Sunny
A33: 0.45833333 | B33: 4162 | C33: 84 | D33: 72 | E33: 81 | F33: Bled down 19oz 4163-4146
A34: 0.46875 | B34: 4149 | C34: 86 | D34: 72 | E34: 80 | F34: Sunny
... A48: 0.61458333 | B48: 4155 | C48: 92 | D48: 72 | E48: 79 | F48: Sunny
A50: Time: | B50: Pressure | C50: Ambient | D50: Pipe | E50: Ground | F50: Comments / Remarks
A51: 0.625 | B51: 4153 | C51: 90 | D51: 72 | E51: 79 | F51: Partly Cloudy
A52: 0.63541667 | B52: 4156 | C52: 92 | D52: 72 | E52: 79 | F52: Partly Cloudy
A53: 0.64583333 | B53: 4157 | C53: 92 | D53: 72 | E53: 79 | F53: Partly Cloudy
A54: 0.65625 | B54: 4155 | C54: 90 | D54: 72 | E54: 79 | F54: Sunny
A55: 0.66666667 | B55: 4150 | C55: 92 | D55: 72 | E55: 79 | F55: Sunny
...

Sheet Summary
F1: PO Box 663
F2: 1721 HCR 3106
F3: Hillsboro, Texas 76645
F4: Office: 254-582-0205
F5: BobcatContracting.com
A8: Length: | B8: 2046 | C8: ft
A9: ID: | B9: 4 | C9: In | D9: Location From: | G9: Location To:
A10: Volume: | B10: 1367 | C10: US Gallon | E10: =LOG!B19 -> 33.7132610, -98.1230730 | H10: =LOG!B20 -> 33.7180270, -98.1248640
A12: Pipeline Data
A13: O.D. | B13: W.T. | C13: Grade | D13: Length | E13: Buried Pipe | F13: Exposed Pipe | G13: Remarks
A14: 4.5" | B14: 0.237" | C14: x42 | D14: 2039' | E14: x | F14: x
A15: 4.5" | B15: 0.337" | C15: x52 | D15: 6.5' | E15: x
A20: This is to certify that the system was tested as outlined below:
A22: Type of Test: | C22: 8 Hour Hydro Test
A23: Test Medium: | C23: Water
A24: Location of Test Unit: | C24: 33.71821895882428, -98.124735682387
A26: Maximum Achieved | C26: =MAX(LOG!B27:B61) -> 4167 | D26: pslg | E26: Minumum Achieved | G26: =MIN(LOG!B27:B61) -> 4145 | H26: pslg
A28: The table below indicates the parameters that the pipeline was tested to:
C30: Testing Parameters (Actual)
C31: Pressure | D31: Temperature
C32: pslg | D32: Ambient | E32: Pipe | F32: Ground
A33: Maximum Achieved | C33: =C26 -> 4167 | D33: =MAX(LOG!C27:C61) -> 98 | E33: =MAX(LOG!D27:D61) -> 72 | F33: =MAX(LOG!E27:E61) -> 83
A34: Minumum Achieved | C34: =G26 -> 4145 | D34: =MIN(LOG!C27:C61) -> 76 | E34: =MIN(LOG!D27:D61) -> 72 | F34: =MIN(LOG!E27:E61) -> 79
C36: Duration of Test, excluding pressurization period
C37: Time | D37: Date | E37: Start Pressure
B38: From: | C38: =LOG!A27 -> 0.39583333 | D38: =LOG!G9 -> 46263 | E38: =LOG!B27 -> 4160
C39: Time | D39: Date | E39: Final Pressure
B40: To: | C40: =LOG!A61 -> 0.72916667 | D40: =LOG!G9 -> 46263 | E40: =LOG!B61 -> 4147
A42: Approval: | D42: Signature | F42: Date
A43: Bobcat:
A44: Client:
A45: Inspector:

Sheet Test Stroke Count
A5: Pressure Test Stroke Count
A6: Owner | C6: Atmos Energy | J6: AFE/Auth | K6: =LOG!G7 -> 180.64635
A7: Contractor | C7: Bobcat Contracting | J7: Project Name | K7: WL-248
A8: Owner's Rep / Insp | C8: Scott Beatty
A9: Service | C9: Gas | J9: Location | K9: =LOG!G8 -> Henrietta, Tx
A10: =Summary!D14 -> 2039' | D10: =Summary!A14 -> 4.5" | F10: =Summary!B14 -> 0.237" | H10: =Summary!C14 -> x42 | J10: Pack Off Pressure | M10: 150
A11: =Summary!D15 -> 6.5' | D11: =Summary!A15 -> 4.5" | F11: =Summary!B15 -> 0.337" | H11: =Summary!C15 -> x52 | J11: Stabilization Pressure | M11: 136
A12: =Summary!D16 | D12: =Summary!A16 | F12: =Summary!B16 | H12: =Summary!C16 | J12: Stroke Count Starts at | M12: 3100
A13: =Summary!D17 | D13: =Summary!A17 | F13: =Summary!B17 | H13: =Summary!C17 | J13: Target Test Pressure | M13: 4160
J14: Reading Increments | M14: 10
J15: Number of Readings | M15: 106
A16: Begin GPS: | B16: =Summary!E10 -> 33.7132610, -98.1230730 | F16: End GPS: | G16: =Summary!H10 -> 33.7180270, -98.1248640 | J16: Pressure Pump Capacity | M16: 0.0043
A17: Begin GPS: | F17: End GPS: | J17: Calculated Incremental Volume | M17: 0.06076
A18: Begin GPS: | F18: End GPS: | J18: Actual Incremental Volume | M18: 0.08239
A19: Pipeline Fill Field Data
A20: Pressure | B20: Stroke | C20: Difference | D20: Pressure | E20: Stroke | F20: Difference | G20: Pressure | H20: Stroke | I20: Difference | J20: Pressure | K20: Stroke | L20: Difference | M20: Pressure | N20: Stroke | O20: Difference
A21: 3100 | B21: 0 | C21: 0 | D21: 3390 | E21: 516 | F21: =IF(ISBLANK(D21),NA(),E21-B49) -> 19 | G21: 3680 | H21: 1021 | I21: =IF(ISBLANK(G21),NA(),H21-E49) -> 16 | J21: 3970 | K21: 1709 | L21: =IF(ISBLANK(J21),NA(),K21-H49) -> 21 | O21: =IF(ISBLANK(M21),NA(),N21-K49) -> #N/A
A22: 3110 | B22: 10 | C22: =IF(ISBLANK(A22),NA(),B22-B21) -> 10 | D22: 3400 | E22: 535 | F22: =IF(ISBLANK(D22),NA(),E22-E21) -> 19 | G22: 3690 | H22: 1037 | I22: =IF(ISBLANK(G22),NA(),H22-H21) -> 16 | J22: 3980 | K22: 1731 | L22: =IF(ISBLANK(J22),NA(),K22-K21) -> 22 | O22: =IF(ISBLANK(M22),NA(),N22-N21) -> #N/A
A23: 3120 | B23: 24 | C23: =IF(ISBLANK(A23),NA(),B23-B22) -> 14 | D23: 3410 | E23: 554 | F23: =IF(ISBLANK(D23),NA(),E23-E22) -> 19 | G23: 3700 | H23: 1054 | I23: =IF(ISBLANK(G23),NA(),H23-H22) -> 17 | J23: 3990 | K23: 1751 | L23: =IF(ISBLANK(J23),NA(),K23-K22) -> 20 | O23: =IF(ISBLANK(M23),NA(),N23-N22) -> #N/A
A24: 3130 | B24: 39 | C24: =IF(ISBLANK(A24),NA(),B24-B23) -> 15 | D24: 3420 | E24: 570 | F24: =IF(ISBLANK(D24),NA(),E24-E23) -> 16 | G24: 3710 | H24: 1071 | I24: =IF(ISBLANK(G24),NA(),H24-H23) -> 17 | J24: 4000 | K24: 1772 | L24: =IF(ISBLANK(J24),NA(),K24-K23) -> 21 | O24: =IF(ISBLANK(M24),NA(),N24-N23) -> #N/A
A25: 3140 | B25: 56 | C25: =IF(ISBLANK(A25),NA(),B25-B24) -> 17 | D25: 3430 | E25: 587 | F25: =IF(ISBLANK(D25),NA(),E25-E24) -> 17 | G25: 3720 | H25: 1100 | I25: =IF(ISBLANK(G25),NA(),H25-H24) -> 29 | J25: 4010 | K25: 1789 | L25: =IF(ISBLANK(J25),NA(),K25-K24) -> 17 | O25: =IF(ISBLANK(M25),NA(),N25-N24) -> #N/A
A26: 3150 | B26: 72 | C26: =IF(ISBLANK(A26),NA(),B26-B25) -> 16 | D26: 3440 | E26: 605 | F26: =IF(ISBLANK(D26),NA(),E26-E25) -> 18 | G26: 3730 | H26: 1128 | I26: =IF(ISBLANK(G26),NA(),H26-H25) -> 28 | J26: 4020 | K26: 1804 | L26: =IF(ISBLANK(J26),NA(),K26-K25) -> 15 | O26: =IF(ISBLANK(M26),NA(),N26-N25) -> #N/A
A27: 3160 | B27: 88 | C27: =IF(ISBLANK(A27),NA(),B27-B26) -> 16 | D27: 3450 | E27: 621 | F27: =IF(ISBLANK(D27),NA(),E27-E26) -> 16 | G27: 3740 | H27: 1152 | I27: =IF(ISBLANK(G27),NA(),H27-H26) -> 24 | J27: 4030 | K27: 1814 | L27: =IF(ISBLANK(J27),NA(),K27-K26) -> 10 | O27: =IF(ISBLANK(M27),NA(),N27-N26) -> #N/A
A28: 3170 | B28: 106 | C28: =IF(ISBLANK(A28),NA(),B28-B27) -> 18 | D28: 3460 | E28: 637 | F28: =IF(ISBLANK(D28),NA(),E28-E27) -> 16 | G28: 3750 | H28: 1178 | I28: =IF(ISBLANK(G28),NA(),H28-H27) -> 26 | J28: 4040 | K28: 1830 | L28: =IF(ISBLANK(J28),NA(),K28-K27) -> 16 | O28: =IF(ISBLANK(M28),NA(),N28-N27) -> #N/A
A29: 3180 | B29: 123 | C29: =IF(ISBLANK(A29),NA(),B29-B28) -> 17 | D29: 3470 | E29: 654 | F29: =IF(ISBLANK(D29),NA(),E29-E28) -> 17 | G29: 3760 | H29: 1209 | I29: =IF(ISBLANK(G29),NA(),H29-H28) -> 31 | J29: 4050 | K29: 1854 | L29: =IF(ISBLANK(J29),NA(),K29-K28) -> 24 | O29: =IF(ISBLANK(M29),NA(),N29-N28) -> #N/A
A30: 3190 | B30: 140 | C30: =IF(ISBLANK(A30),NA(),B30-B29) -> 17 | D30: 3480 | E30: 671 | F30: =IF(ISBLANK(D30),NA(),E30-E29) -> 17 | G30: 3770 | H30: 1231 | I30: =IF(ISBLANK(G30),NA(),H30-H29) -> 22 | J30: 4060 | K30: 1865 | L30: =IF(ISBLANK(J30),NA(),K30-K29) -> 11 | O30: =IF(ISBLANK(M30),NA(),N30-N29) -> #N/A
A31: 3200 | B31: 158 | C31: =IF(ISBLANK(A31),NA(),B31-B30) -> 18 | D31: 3490 | E31: 687 | F31: =IF(ISBLANK(D31),NA(),E31-E30) -> 16 | G31: 3780 | H31: 1266 | I31: =IF(ISBLANK(G31),NA(),H31-H30) -> 35 | J31: 4070 | K31: 1880 | L31: =IF(ISBLANK(J31),NA(),K31-K30) -> 15 | O31: =IF(ISBLANK(M31),NA(),N31-N30) -> #N/A
A32: 3210 | B32: 175 | C32: =IF(ISBLANK(A32),NA(),B32-B31) -> 17 | D32: 3500 | E32: 707 | F32: =IF(ISBLANK(D32),NA(),E32-E31) -> 20 | G32: 3790 | H32: 1309 | I32: =IF(ISBLANK(G32),NA(),H32-H31) -> 43 | J32: 4080 | K32: 1896 | L32: =IF(ISBLANK(J32),NA(),K32-K31) -> 16 | O32: =IF(ISBLANK(M32),NA(),N32-N31) -> #N/A
A33: 3220 | B33: 194 | C33: =IF(ISBLANK(A33),NA(),B33-B32) -> 19 | D33: 3510 | E33: 727 | F33: =IF(ISBLANK(D33),NA(),E33-E32) -> 20 | G33: 3800 | H33: 1358 | I33: =IF(ISBLANK(G33),NA(),H33-H32) -> 49 | J33: 4090 | K33: 1911 | L33: =IF(ISBLANK(J33),NA(),K33-K32) -> 15 | O33: =IF(ISBLANK(M33),NA(),N33-N32) -> #N/A
... A40: 3290 | B40: 327 | C40: =IF(ISBLANK(A40),NA(),B40-B39) -> 20 | D40: 3580 | E40: 854 | F40: =IF(ISBLANK(D40),NA(),E40-E39) -> 17 | G40: 3870 | H40: 1499 | I40: =IF(ISBLANK(G40),NA(),H40-H39) -> 21 | J40: 4160 | K40: 2031 | L40: =IF(ISBLANK(J40),NA(),K40-K39) -> 17 | O40: =IF(ISBLANK(M40),NA(),N40-N39) -> #N/A
A41: 3300 | B41: 344 | C41: =IF(ISBLANK(A41),NA(),B41-B40) -> 17 | D41: 3590 | E41: 871 | F41: =IF(ISBLANK(D41),NA(),E41-E40) -> 17 | G41: 3880 | H41: 1519 | I41: =IF(ISBLANK(G41),NA(),H41-H40) -> 20 | L41: =IF(ISBLANK(J41),NA(),K41-K40) -> #N/A | O41: =IF(ISBLANK(M41),NA(),N41-N40) -> #N/A
A42: 3310 | B42: 364 | C42: =IF(ISBLANK(A42),NA(),B42-B41) -> 20 | D42: 3600 | E42: 888 | F42: =IF(ISBLANK(D42),NA(),E42-E41) -> 17 | G42: 3890 | H42: 1541 | I42: =IF(ISBLANK(G42),NA(),H42-H41) -> 22 | L42: =IF(ISBLANK(J42),NA(),K42-K41) -> #N/A | O42: =IF(ISBLANK(M42),NA(),N42-N41) -> #N/A
A43: 3320 | B43: 382 | C43: =IF(ISBLANK(A43),NA(),B43-B42) -> 18 | D43: 3610 | E43: 904 | F43: =IF(ISBLANK(D43),NA(),E43-E42) -> 16 | G43: 3900 | H43: 1560 | I43: =IF(ISBLANK(G43),NA(),H43-H42) -> 19 | L43: =IF(ISBLANK(J43),NA(),K43-K42) -> #N/A | O43: =IF(ISBLANK(M43),NA(),N43-N42) -> #N/A
A44: 3330 | B44: 401 | C44: =IF(ISBLANK(A44),NA(),B44-B43) -> 19 | D44: 3620 | E44: 921 | F44: =IF(ISBLANK(D44),NA(),E44-E43) -> 17 | G44: 3910 | H44: 1579 | I44: =IF(ISBLANK(G44),NA(),H44-H43) -> 19 | L44: =IF(ISBLANK(J44),NA(),K44-K43) -> #N/A | O44: =IF(ISBLANK(M44),NA(),N44-N43) -> #N/A
A45: 3340 | B45: 419 | C45: =IF(ISBLANK(A45),NA(),B45-B44) -> 18 | D45: 3630 | E45: 938 | F45: =IF(ISBLANK(D45),NA(),E45-E44) -> 17 | G45: 3920 | H45: 1603 | I45: =IF(ISBLANK(G45),NA(),H45-H44) -> 24 | L45: =IF(ISBLANK(J45),NA(),K45-K44) -> #N/A | O45: =IF(ISBLANK(M45),NA(),N45-N44) -> #N/A
A46: 3350 | B46: 439 | C46: =IF(ISBLANK(A46),NA(),B46-B45) -> 20 | D46: 3640 | E46: 954 | F46: =IF(ISBLANK(D46),NA(),E46-E45) -> 16 | G46: 3930 | H46: 1627 | I46: =IF(ISBLANK(G46),NA(),H46-H45) -> 24 | L46: =IF(ISBLANK(J46),NA(),K46-K45) -> #N/A | O46: =IF(ISBLANK(M46),NA(),N46-N45) -> #N/A
A47: 3360 | B47: 458 | C47: =IF(ISBLANK(A47),NA(),B47-B46) -> 19 | D47: 3650 | E47: 972 | F47: =IF(ISBLANK(D47),NA(),E47-E46) -> 18 | G47: 3940 | H47: 1648 | I47: =IF(ISBLANK(G47),NA(),H47-H46) -> 21 | L47: =IF(ISBLANK(J47),NA(),K47-K46) -> #N/A | O47: =IF(ISBLANK(M47),NA(),N47-N46) -> #N/A
A48: 3370 | B48: 479 | C48: =IF(ISBLANK(A48),NA(),B48-B47) -> 21 | D48: 3660 | E48: 987 | F48: =IF(ISBLANK(D48),NA(),E48-E47) -> 15 | G48: 3950 | H48: 1667 | I48: =IF(ISBLANK(G48),NA(),H48-H47) -> 19 | L48: =IF(ISBLANK(J48),NA(),K48-K47) -> #N/A | O48: =IF(ISBLANK(M48),NA(),N48-N47) -> #N/A
A49: 3380 | B49: 497 | C49: =IF(ISBLANK(A49),NA(),B49-B48) -> 18 | D49: 3670 | E49: 1005 | F49: =IF(ISBLANK(D49),NA(),E49-E48) -> 18 | G49: 3960 | H49: 1688 | I49: =IF(ISBLANK(G49),NA(),H49-H48) -> 21 | L49: =IF(ISBLANK(J49),NA(),K49-K48) -> #N/A | O49: =IF(ISBLANK(M49),NA(),N49-N48) -> #N/A
A51: Total Volume Pumped | D51: 8.7333 | H51: Total Pressure Increase | J51: 1060 | L51: Double Deviation? Yes or No | N51: NO
...
